pi@raspberrypi:~/Desktop/SIH $ python3 app.py 
Traceback (most recent call last):
  File "app.py", line 13, in <module>
    model = tf.keras.models.load_model("plant_disease_model.h5")
  File "/home/pi/.local/lib/python3.7/site-packages/tensorflow/python/keras/saving/save.py", line 184, in load_model
    return hdf5_format.load_model_from_hdf5(filepath, custom_objects, compile)
  File "/home/pi/.local/lib/python3.7/site-packages/tensorflow/python/keras/saving/hdf5_format.py", line 178, in load_model_from_hdf5
    custom_objects=custom_objects)
  File "/home/pi/.local/lib/python3.7/site-packages/tensorflow/python/keras/saving/model_config.py", line 55, in model_from_config
    return deserialize(config, custom_objects=custom_objects)
  File "/home/pi/.local/lib/python3.7/site-packages/tensorflow/python/keras/layers/serialization.py", line 109, in deserialize
    printable_module_name='layer')
  File "/home/pi/.local/lib/python3.7/site-packages/tensorflow/python/keras/utils/generic_utils.py", line 373, in deserialize_keras_object
    list(custom_objects.items())))
  File "/home/pi/.local/lib/python3.7/site-packages/tensorflow/python/keras/engine/sequential.py", line 398, in from_config
    custom_objects=custom_objects)
  File "/home/pi/.local/lib/python3.7/site-packages/tensorflow/python/keras/layers/serialization.py", line 109, in deserialize
    printable_module_name='layer')
  File "/home/pi/.local/lib/python3.7/site-packages/tensorflow/python/keras/utils/generic_utils.py", line 375, in deserialize_keras_object
    return cls.from_config(cls_config)
  File "/home/pi/.local/lib/python3.7/site-packages/tensorflow/python/keras/engine/base_layer.py", line 655, in from_config
    return cls(**config)
  File "/home/pi/.local/lib/python3.7/site-packages/tensorflow/python/keras/layers/convolutional.py", line 599, in __init__
    **kwargs)
  File "/home/pi/.local/lib/python3.7/site-packages/tensorflow/python/keras/layers/convolutional.py", line 125, in __init__
    **kwargs)
  File "/home/pi/.local/lib/python3.7/site-packages/tensorflow/python/training/tracking/base.py", line 456, in _method_wrapper
    result = method(self, *args, **kwargs)
  File "/home/pi/.local/lib/python3.7/site-packages/tensorflow/python/keras/engine/base_layer.py", line 294, in __init__
    generic_utils.validate_kwargs(kwargs, allowed_kwargs)
  File "/home/pi/.local/lib/python3.7/site-packages/tensorflow/python/keras/utils/generic_utils.py", line 792, in validate_kwargs
    raise TypeError(error_message, kwarg)
TypeError: ('Keyword argument not understood:', 'groups')
