Run app.py
2025-09-22 16:57:20.837054: E tensorflow/core/platform/hadoop/hadoop_file_system.cc:132] HadoopFileSystem load error: libhdfs.so: cannot open shared object file: No such file or directory
Traceback (most recent call last):
  File "/home/pi/Desktop/SIH/app.py", line 13, in <module>
    model = tf.keras.models.load_model("\\home\\pi\\Desktop\\SIH\\plant_disease_model.h5")
  File "/home/pi/.local/lib/python3.7/site-packages/tensorflow_core/python/keras/saving/save.py", line 149, in load_model
    loader_impl.parse_saved_model(filepath)
  File "/home/pi/.local/lib/python3.7/site-packages/tensorflow_core/python/saved_model/loader_impl.py", line 83, in parse_saved_model
    constants.SAVED_MODEL_FILENAME_PB))
OSError: SavedModel file does not exist at: \home\pi\Desktop\SIH\plant_disease_model.h5/{saved_model.pbtxt|saved_model.pb}
>>> 
